<robot name="car">
  <link name="base_link">
    <visual>
       <geometry>
         <box size="0.2 .3 .1"/>
       </geometry>
       <origin rpy="0 0 0" xyz="0 0 0.05"/>
    </visual>
  </link>
 
  <link name="wheel_1">
    <visual>
      <geometry>
        <cylinder length="0.05" radius="0.05"/>
      </geometry>
      <origin rpy="0 1.5 0" xyz="0.1 0.1 0"/>
    </visual>
  </link>
 
  <link name="wheel_2">
    <visual>
      <geometry>
        <cylinder length="0.05" radius="0.05"/>
      </geometry>
      <origin rpy="0 1.5 0" xyz="-0.1 0.1 0"/>
    </visual>
  </link>
 
  <link name="wheel_3">
    <visual>
      <geometry>
        <cylinder length="0.05" radius="0.05"/>
      </geometry>
      <origin rpy="0 1.5 0" xyz="0.1 -0.1 0"/>
    </visual>
  </link>
 
  <link name="wheel_4">
    <visual>
      <geometry>
        <cylinder length="0.05" radius="0.05"/>
      </geometry>
      <origin rpy="0 1.5 0" xyz="-0.1 -0.1 0"/>
    </visual>
  </link>
  <link name="base">
    <visual>
      <geometry>
        <box size="0.2 .3 .09"/>
      </geometry>
      <origin rpy="0 0 0" xyz="0 0 0.15"/>
    </visual>
  </link>
  <link name="back">
    <visual>
      <geometry>
        <box size="0.3 .05 .29"/>
      </geometry>
      <origin rpy="0 0 0" xyz="0 0.15 0.35"/>
    </visual>
  </link>

 
  <joint name="joint_base_wheel1" type="fixed">
    <parent link="base_link"/>
    <child link="wheel_1"/>
  </joint>
 
  <joint name="joint_base_wheel2" type="fixed">
    <parent link="base_link"/>
    <child link="wheel_2"/>
  </joint>
 
  <joint name="joint_base_wheel3" type="fixed">
    <parent link="base_link"/>
    <child link="wheel_3"/>
  </joint>
 
  <joint name="joint_base_wheel4" type="fixed">
    <parent link="base_link"/>
    <child link="wheel_4"/>
  </joint>
  <joint name="joint_base" type="continuous">
    <parent link="base_link"/>
    <child link="base"/>
    <axis xyz="1.0 0.0 0.0"/>
  </joint>
  <joint name="joint_back" type="continuous">
    <parent link="base"/>
    <child link="back"/>
    <axis xyz="1.0 0.0 0.0"/>
  </joint>

</robot>
